<?xml version="1.0"?>
<robot name="cart_double_pendulum">

  <link name="world" />

  <joint name="world_to_base_link" type="fixed">
    <parent link="world"/>
    <child link="slideBar"/>
  </joint>

  <link name="slideBar">
    <visual>
      <geometry>
        <box size="30 0.05 0.05"/>
      </geometry>
      <origin xyz="0 0 0"/>
      <material name="green">
        <color rgba="0 0.8 .8 1"/>
      </material>
    </visual>
    <inertial>
      <mass value="0.6"/>
      <inertia ixx="1.0" ixy="0.0" ixz="0.0" iyy="1.0" iyz="0.0" izz="1.0"/>
    </inertial>
  </link>

  <!-- Cart Link -->
  <link name="cart">
    <inertial>
      <mass value="0.6"/>
      <origin xyz="0 0 0" rpy="0 0 0"/>
      <inertia ixx="0.001" iyy="0.001" izz="0.001" ixy="0" ixz="0" iyz="0"/>
    </inertial>
    <visual>
      <origin xyz="0 0 0" rpy="0 0 0"/>
      <geometry>
        <box size="0.1 0.1 0.05"/>
      </geometry>
      <material name="blue">
        <color rgba="0 0 1 1"/>
      </material>
    </visual>
  </link>

  <!-- First Light Rod (link1) -->
  <link name="link1">
    <visual>
      <origin xyz="0 0 -0.25" rpy="0 0 0"/>
      <geometry>
        <cylinder radius="0.01" length="0.5"/>
      </geometry>
      <material name="red">
        <color rgba="1 0 0 1"/>
      </material>
    </visual>
    <inertial>
      <origin xyz="0 0 -0.25" rpy="0 0 0"/>
      <mass value="0.2"/>
      <inertia ixx="4.1667e-3" iyy="4.1667e-3" izz="4.1667e-3" ixy="0" ixz="0" iyz="0"/>
    </inertial>
  </link>

  <!-- Second Light Rod (link2) -->
  <link name="link2">
    <visual>
      <origin xyz="0 0 -0.25" rpy="0 0 0"/>
      <geometry>
        <cylinder radius="0.01" length="0.5"/>
      </geometry>
      <material name="green">
        <color rgba="0 1 0 1"/>
      </material>
    </visual>
    <inertial>
      <origin xyz="0 0 -0.25" rpy="0 0 0"/>
      <mass value="0.2"/>
      <inertia ixx="4.1667e-3" iyy="4.1667e-3" izz="4.1667e-3" ixy="0" ixz="0" iyz="0"/>
    </inertial>
  </link>

  <!-- Joints -->
  <joint name="slider_to_cart" type="prismatic">
    <axis xyz="1 0 0"/>
    <origin xyz="0.0 0.0 0.0"/>
    <parent link="slideBar"/>
    <child link="cart"/>
    <limit effort="1000.0" lower="-2" upper="2" velocity="5"/>
    <dynamics damping="1.0" friction="0.5"/>
  </joint> 

  <!-- Revolute Joint for Link1 -->
  <joint name="hinge1" type="revolute">
    <parent link="cart"/>
    <child link="link1"/>
    <origin xyz="0 0 0" rpy="0 0 0"/>
    <axis xyz="0 1 0"/>
    <limit effort="100" velocity="5" lower="-3.14159" upper="3.14159"/>
    <dynamics damping="0.1"/>
  </joint>

  <!-- Revolute Joint for Link2 (directly after link1) -->
  <joint name="hinge2" type="revolute">
    <parent link="link1"/>
    <child link="link2"/>
    <origin xyz="0 0 -0.5" rpy="0 0 0"/>
    <axis xyz="0 1 0"/>
    <limit effort="100" velocity="10" lower="-3.14159" upper="3.14159"/>
    <dynamics damping="0.1"/>
  </joint>

</robot>
